<?xml version="1.0"?>
<robot name="mi_primer_robot">

    <material name="green">
        <color rgba=" 0 0.8 0 1"/>
    </material>

    <material name="grey">
        <color rgba="0.75 0.75 0.75 1"/>
    </material>

    <material name="red">
        <color rgba="0.0 0 0 1"/>
    </material>

    <material name="blue">
        <color rgba="0 0 0.8 1"/>
    </material>

    <material name="white">
        <color rgba="1.0 1.0 1.0 1"/>
    </material>

    <material name="black">
        <color rgba="0.0 0.0 0.0 1"/>    
    </material>

    <link name="base_link">
        <visual>
        <origin rpy="0 0 0" xyz="0 0 0"/>
        <geometry>
            <cylinder radius="0.1" length="0.07"/>
        </geometry>
        <material name="green"/>
        </visual>    
    </link>


    <link name="wheel_left_link">
        <visual>
            <geometry>
                <mesh filename="package://mis_modelos_robots/meshes/kobuki_meshes/wheel.dae"/>
            </geometry>
            <origin rpy="0 0 0" xyz="0 0 0"/>
        </visual>
    </link>


    <joint name="wheel_left_joint" type="continuous">
        <parent link="base_link"/>
        <child link="wheel_left_link"/>
        <origin rpy="-1.57079632679 0 0" xyz="0.00 0.0615 -0.045"/>
        <axis xyz="0 0 1"/>
    </joint>


    <link name="wheel_right_link">
        <visual>
            <geometry>
                <mesh filename="package://mis_modelos_robots/meshes/kobuki_meshes/wheel.dae"/>
            </geometry>
            <origin rpy="0 0 0" xyz="0 0 0"/>
        </visual>
    </link>


    <joint name="wheel_right_joint" type="continuous">
        <parent link="base_link"/>
        <child link="wheel_right_link"/>
        <origin rpy="-1.57079632679 0 0" xyz="0.00 -0.0615 -0.045"/>
        <axis xyz="0 0 1"/>
    </joint>




</robot>