<?xml version="1.0" encoding="UTF-8"?>
<robot name="turtlebot_visual">


<!-- BASE DEL ROBOT -->

<link name="base_footprint"/>

<link name="base_link">
      <visual>
         <geometry>
            <!-- new mesh -->
            <mesh filename="package://my_mira_description/meshes/kobuki_meshes/main_body.dae"/>
         </geometry>
         <origin rpy="0 0 0" xyz="0.001 0 0.05199"/>
      </visual>

      <collision>
         <geometry>
            <cylinder length="0.10938" radius="0.178"/>
         </geometry>
         <origin rpy="0 0 0" xyz="0.0 0 0.05949"/>
      </collision>
      
      <inertial>
         <!-- COM experimentally determined -->
         <origin xyz="0.01 0 0"/>
         <mass value="2.4"/>
      <!-- 2.4/2.6 kg for small/big battery pack -->
      <!-- Kobuki's inertia tensor is approximated by a cylinder with homogeneous mass distribution
             More details: http://en.wikipedia.org/wiki/List_of_moment_of_inertia_tensors
             m = 2.4 kg; h = 0.09 m; r = 0.175 m
             ixx = 1/12 * m * (3 * r^2 + h^2)
             iyy = 1/12 * m * (3 * r^2 + h^2)
             izz = 1/2 * m * r^2 
          -->
         <inertia ixx="0.019995" ixy="0.0" ixz="0.0" iyy="0.019995" iyz="0.0" izz="0.03675"/>
      </inertial>

</link>


<gazebo reference="base_link">
      <mu1>0.3</mu1>
      <mu2>0.3</mu2>
      <sensor name="bumpers" type="contact">
         <always_on>1</always_on>
         <update_rate>50.0</update_rate>
         <visualize>true</visualize>
         <contact>
            <collision>base_footprint_collision_base_link</collision>
         </contact>
      </sensor>
</gazebo>

 <joint name="base_joint" type="fixed">
      <origin rpy="0 0 0" xyz="0 0 0.0102"/>
      <parent link="base_footprint"/>
      <child link="base_link"/>
</joint>


<link name="wheel_left_link">
      <visual>
         <geometry>
            <mesh filename="package://my_mira_description/meshes/kobuki_meshes/wheel.dae"/>
         </geometry>
         <origin rpy="0 0 0" xyz="0 0 0"/>
      </visual>

    <collision>
         <geometry>
            <cylinder length="0.0206" radius="0.0350"/>
         </geometry>
         <origin rpy="0 0 0" xyz="0 0 0"/>
      </collision>
      <inertial>
         <mass value="0.01"/>
         <origin xyz="0 0 0"/>
         <inertia ixx="0.001" ixy="0.0" ixz="0.0" iyy="0.001" iyz="0.0" izz="0.001"/>
      </inertial>


</link>


<gazebo reference="wheel_left_link">
      <mu1>1.0</mu1>
      <mu2>1.0</mu2>
      <kp>1000000.0</kp>
      <kd>100.0</kd>
      <minDepth>0.001</minDepth>
      <maxVel>1.0</maxVel>
</gazebo>


 <joint name="wheel_left_joint" type="continuous">
      <parent link="base_link"/>
      <child link="wheel_left_link"/>
      <origin rpy="-1.57079632679 0 0" xyz="0.00 0.115 0.0250"/>
      <axis xyz="0 0 1"/>
   </joint>


<link name="wheel_right_link">
      <visual>
         <geometry>
            <mesh filename="package://my_mira_description/meshes/kobuki_meshes/wheel.dae"/>
         </geometry>
         <origin rpy="0 0 0" xyz="0 0 0"/>
      </visual>

    <collision>
         <geometry>
            <cylinder length="0.0206" radius="0.0350"/>
         </geometry>
         <origin rpy="0 0 0" xyz="0 0 0"/>
      </collision>
      <inertial>
         <mass value="0.01"/>
         <origin xyz="0 0 0"/>
         <inertia ixx="0.001" ixy="0.0" ixz="0.0" iyy="0.001" iyz="0.0" izz="0.001"/>
      </inertial>

</link>

<gazebo reference="wheel_right_link">
      <mu1>1.0</mu1>
      <mu2>1.0</mu2>
      <kp>1000000.0</kp>
      <kd>100.0</kd>
      <minDepth>0.001</minDepth>
      <maxVel>1.0</maxVel>
</gazebo>


<joint name="wheel_right_joint" type="continuous">
      <parent link="base_link"/>
      <child link="wheel_right_link"/>
      <origin rpy="-1.57079632679 0 0" xyz="0.00 -0.115 0.0250"/>
      <axis xyz="0 0 1"/>
</joint>


<link name="caster_front_link">
      <visual>
         <geometry>
            <cylinder length="0.0176" radius="0.017"/>
         </geometry>
         <origin rpy="0 0 0" xyz="0 0 0"/>
      </visual>

     <collision>
         <geometry>
            <cylinder length="0.0176" radius="0.017"/>
         </geometry>
         <origin rpy="0 0 0" xyz="0 0 0"/>
      </collision>
      <inertial>
         <mass value="0.01"/>
         <origin xyz="0 0 0"/>
         <inertia ixx="0.001" ixy="0.0" ixz="0.0" iyy="0.001" iyz="0.0" izz="0.001"/>
      </inertial>

</link>

  <gazebo reference="caster_front_link">
      <mu1>0.0</mu1>
      <mu2>0.0</mu2>
      <kp>1000000.0</kp>
      <kd>100.0</kd>
      <minDepth>0.001</minDepth>
      <maxVel>1.0</maxVel>
   </gazebo>

<joint name="caster_front_joint" type="continuous">
      <parent link="base_link"/>
      <child link="caster_front_link"/>
      <origin rpy="-1.57079632679 0 0" xyz="0.115 0.0 0.007"/>
      <axis xyz="0 0 1"/>
</joint>

 <link name="caster_back_link">
      <visual>
         <geometry>
            <cylinder length="0.0176" radius="0.017"/>
         </geometry>
         <origin rpy="0 0 0" xyz="0 0 0"/>
      </visual>

     <collision>
         <geometry>
            <cylinder length="0.0176" radius="0.017"/>
         </geometry>
         <origin rpy="0 0 0" xyz="0 0 0"/>
      </collision>
      <inertial>
         <mass value="0.01"/>
         <origin xyz="0 0 0"/>
         <inertia ixx="0.001" ixy="0.0" ixz="0.0" iyy="0.001" iyz="0.0" izz="0.001"/>
      </inertial>

   </link>

<gazebo reference="caster_back_link">
      <mu1>0.0</mu1>
      <mu2>0.0</mu2>
      <kp>1000000.0</kp>
      <kd>100.0</kd>
      <minDepth>0.001</minDepth>
      <maxVel>1.0</maxVel>
</gazebo>



<joint name="caster_back_joint" type="continuous">
      <parent link="base_link"/>
      <child link="caster_back_link"/>
      <origin rpy="-1.57079632679 0 0" xyz="-0.135 0.0 0.009"/>
      <axis xyz="0 0 1"/>
</joint>

<!-- ESTRUCTURA ENCIMA DE LA BASE -->

<!-- palitos.... -->

<link name="pole_bottom_0_link">
      <visual>
         <origin rpy="0 0 0" xyz="0 0 0"/>
         <geometry>
            <mesh filename="package://my_mira_description/meshes/kobuki_meshes/stacks/hexagons/pole_bottom.dae"/>
         </geometry>
      </visual>
      <collision>
         <origin rpy="0 0 0" xyz="0 0 0"/>
         <geometry>
            <cylinder length="0.0492" radius="0.006"/>
         </geometry>
      </collision>
      <inertial>
         <mass value="0.008"/>
         <origin rpy="0 0 0" xyz="0 0 0"/>
         <inertia ixx="0.000001686" ixy="0.0" ixz="0.0" iyy="0.000001686" iyz="0.0" izz="0.000000144"/>
      </inertial>
</link>


<joint name="pole_bottom_0_joint" type="fixed">
      <origin rpy="0 0 0" xyz="0.12 0.082    0.1028"/>
      <parent link="base_link"/>
      <child link="pole_bottom_0_link"/>
</joint>


<link name="pole_bottom_1_link">
      <visual>
         <origin rpy="0 0 0" xyz="0 0 0"/>
         <geometry>
            <mesh filename="package://my_mira_description/meshes/kobuki_meshes/stacks/hexagons/pole_bottom.dae"/>
         </geometry>
      </visual>
      <collision>
         <origin rpy="0 0 0" xyz="0 0 0"/>
         <geometry>
            <cylinder length="0.0492" radius="0.006"/>
         </geometry>
      </collision>
      <inertial>
         <mass value="0.008"/>
         <origin rpy="0 0 0" xyz="0 0 0"/>
         <inertia ixx="0.000001686" ixy="0.0" ixz="0.0" iyy="0.000001686" iyz="0.0" izz="0.000000144"/>
      </inertial>
</link>

<joint name="pole_bottom_1_joint" type="fixed">
      <origin rpy="0 0 0" xyz="0.055 0.12 0.1028"/>
      <parent link="base_link"/>
      <child link="pole_bottom_1_link"/>
</joint>



<link name="pole_bottom_2_link">
      <visual>
         <origin rpy="0 0 0" xyz="0 0 0"/>
         <geometry>
            <mesh filename="package://my_mira_description/meshes/kobuki_meshes/stacks/hexagons/pole_bottom.dae"/>
         </geometry>
      </visual>
      <collision>
         <origin rpy="0 0 0" xyz="0 0 0"/>
         <geometry>
            <cylinder length="0.0492" radius="0.006"/>
         </geometry>
      </collision>
      <inertial>
         <mass value="0.008"/>
         <origin rpy="0 0 0" xyz="0 0 0"/>
         <inertia ixx="0.000001686" ixy="0.0" ixz="0.0" iyy="0.000001686" iyz="0.0" izz="0.000000144"/>
      </inertial>
</link>

<joint name="pole_bottom_2_joint" type="fixed">
      <origin rpy="0 0 0" xyz="-0.055 0.12 0.1028"/>
      <parent link="base_link"/>
      <child link="pole_bottom_2_link"/>
</joint>


<link name="pole_bottom_3_link">
      <visual>
         <origin rpy="0 0 0" xyz="0 0 0"/>
         <geometry>
            <mesh filename="package://my_mira_description/meshes/kobuki_meshes/stacks/hexagons/pole_bottom.dae"/>
         </geometry>
      </visual>
      <collision>
         <origin rpy="0 0 0" xyz="0 0 0"/>
         <geometry>
            <cylinder length="0.0492" radius="0.006"/>
         </geometry>
      </collision>
      <inertial>
         <mass value="0.008"/>
         <origin rpy="0 0 0" xyz="0 0 0"/>
         <inertia ixx="0.000001686" ixy="0.0" ixz="0.0" iyy="0.000001686" iyz="0.0" izz="0.000000144"/>
      </inertial>
</link>


<joint name="pole_bottom_3_joint" type="fixed">
      <origin rpy="0 0 0" xyz="0.12 -0.082 0.1028"/>
      <parent link="base_link"/>
      <child link="pole_bottom_3_link"/>
</joint>
   

<link name="pole_bottom_4_link">
      <visual>
         <origin rpy="0 0 0" xyz="0 0 0"/>
         <geometry>
            <mesh filename="package://my_mira_description/meshes/kobuki_meshes/stacks/hexagons/pole_bottom.dae"/>
         </geometry>
      </visual>
      <collision>
         <origin rpy="0 0 0" xyz="0 0 0"/>
         <geometry>
            <cylinder length="0.0492" radius="0.006"/>
         </geometry>
      </collision>
      <inertial>
         <mass value="0.008"/>
         <origin rpy="0 0 0" xyz="0 0 0"/>
         <inertia ixx="0.000001686" ixy="0.0" ixz="0.0" iyy="0.000001686" iyz="0.0" izz="0.000000144"/>
      </inertial>
</link>


<joint name="pole_bottom_4_joint" type="fixed">
      <origin rpy="0 0 0" xyz="0.055 -0.12 0.1028"/>
      <parent link="base_link"/>
      <child link="pole_bottom_4_link"/>
</joint>

 <joint name="pole_bottom_5_joint" type="fixed">
      <origin rpy="0 0 0" xyz="-0.055 -0.12 0.1028"/>
      <parent link="base_link"/>
      <child link="pole_bottom_5_link"/>
</joint>

<link name="pole_bottom_5_link">
      <visual>
         <origin rpy="0 0 0" xyz="0 0 0"/>
         <geometry>
            <mesh filename="package://my_mira_description/meshes/kobuki_meshes/stacks/hexagons/pole_bottom.dae"/>
         </geometry>
      </visual>
      <collision>
         <origin rpy="0 0 0" xyz="0 0 0"/>
         <geometry>
            <cylinder length="0.0492" radius="0.006"/>
         </geometry>
      </collision>
      <inertial>
         <mass value="0.008"/>
         <origin rpy="0 0 0" xyz="0 0 0"/>
         <inertia ixx="0.000001686" ixy="0.0" ixz="0.0" iyy="0.000001686" iyz="0.0" izz="0.000000144"/>
      </inertial>
</link>


<!-- plataforma.... -->

 <link name="plate_bottom_link">
      <visual>
         <origin rpy="0 0 0" xyz="0 0 0"/>
         <geometry>
            <mesh filename="package://my_mira_description/meshes/kobuki_meshes/stacks/hexagons/plate_bottom.dae"/>
         </geometry>
      </visual>
       <collision>
         <origin rpy="0 0 0" xyz="-0.02364 0 0"/>
         <geometry>
            <cylinder length="0.006" radius="0.170"/>
         </geometry>
      </collision>
      <inertial>
         <mass value="0.520"/>
         <origin xyz="0 0 0"/>
         <inertia ixx="0.003328" ixy="0.0" ixz="0.0" iyy="0.003328" iyz="0.0" izz="0.006656"/>
      </inertial>
</link>

<joint name="plate_bottom_joint" type="fixed">
      <origin rpy="0 0 0" xyz="0.02364 0.0 0.1306"/>
      <parent link="base_link"/>
      <child link="plate_bottom_link"/>
</joint>

<!--SEGUNDA ESTRUCTURA ENCIMA DE LA BASE -->

<!-- palitos.... -->

<link name="pole_middle_0_link">
      <visual>
         <origin rpy="0 3.14159265359 0" xyz="0 0 0"/>
         <geometry>
            <mesh filename="package://my_mira_description/meshes/kobuki_meshes/stacks/hexagons/pole_middle.dae"/>
         </geometry>
      </visual>
      <collision>
         <origin rpy="0 0 0" xyz="0 0 0"/>
         <geometry>
            <cylinder length="0.0608" radius="0.006"/>
         </geometry>
      </collision>
      <inertial>
         <mass value="0.012"/>
         <origin xyz="0 0 0"/>
         <inertia ixx="0.000003805" ixy="0.0" ixz="0.0" iyy="0.000003805" iyz="0.0" izz="0.000000216"/>
      </inertial>
</link>

 <joint name="pole_middle_0_joint" type="fixed">
      <origin rpy="0 0 0" xyz="0.0381 0.1505 0.164"/>
      <parent link="base_link"/>
      <child link="pole_middle_0_link"/>
</joint>
   

<link name="pole_middle_1_link">
      <visual>
         <origin rpy="0 3.14159265359 0" xyz="0 0 0"/>
         <geometry>
            <mesh filename="package://my_mira_description/meshes/kobuki_meshes/stacks/hexagons/pole_middle.dae"/>
         </geometry>
      </visual>
       <collision>
         <origin rpy="0 0 0" xyz="0 0 0"/>
         <geometry>
            <cylinder length="0.0608" radius="0.006"/>
         </geometry>
      </collision>
      <inertial>
         <mass value="0.012"/>
         <origin xyz="0 0 0"/>
         <inertia ixx="0.000003805" ixy="0.0" ixz="0.0" iyy="0.000003805" iyz="0.0" izz="0.000000216"/>
      </inertial>
</link>

<joint name="pole_middle_1_joint" type="fixed">
      <origin rpy="0 0 0" xyz="0.0381 -0.1505 0.164"/>
      <parent link="base_link"/>
      <child link="pole_middle_1_link"/>
</joint>


<link name="pole_middle_2_link">
      <visual>
         <origin rpy="0 3.14159265359 0" xyz="0 0 0"/>
         <geometry>
            <mesh filename="package://my_mira_description/meshes/kobuki_meshes/stacks/hexagons/pole_middle.dae"/>
         </geometry>
      </visual>
      <collision>
         <origin rpy="0 0 0" xyz="0 0 0"/>
         <geometry>
            <cylinder length="0.0608" radius="0.006"/>
         </geometry>
      </collision>
      <inertial>
         <mass value="0.012"/>
         <origin xyz="0 0 0"/>
         <inertia ixx="0.000003805" ixy="0.0" ixz="0.0" iyy="0.000003805" iyz="0.0" izz="0.000000216"/>
      </inertial>
</link>

<joint name="pole_middle_2_joint" type="fixed">
      <origin rpy="0 0 0" xyz="-0.0381 0.1505 0.164"/>
      <parent link="base_link"/>
      <child link="pole_middle_2_link"/>
</joint>


<link name="pole_middle_3_link">
      <visual>
         <origin rpy="0 3.14159265359 0" xyz="0 0 0"/>
         <geometry>
            <mesh filename="package://my_mira_description/meshes/kobuki_meshes/stacks/hexagons/pole_middle.dae"/>
         </geometry>
      </visual>
      <collision>
         <origin rpy="0 0 0" xyz="0 0 0"/>
         <geometry>
            <cylinder length="0.0608" radius="0.006"/>
         </geometry>
      </collision>
      <inertial>
         <mass value="0.012"/>
         <origin xyz="0 0 0"/>
         <inertia ixx="0.000003805" ixy="0.0" ixz="0.0" iyy="0.000003805" iyz="0.0" izz="0.000000216"/>
      </inertial>
</link>

<joint name="pole_middle_3_joint" type="fixed">
      <origin rpy="0 0 0" xyz="-0.0381 -0.1505 0.164"/>
      <parent link="base_link"/>
      <child link="pole_middle_3_link"/>
</joint>


<link name="plate_middle_link">
      <visual>
         <origin rpy="0 0 0" xyz="0 0 0"/>
         <geometry>
            <mesh filename="package://my_mira_description/meshes/kobuki_meshes/stacks/hexagons/plate_middle.dae"/>
         </geometry>
      </visual>
       <collision>
         <origin rpy="0 0 0" xyz="0.01364 0.0 0.0"/>
         <geometry>
            <cylinder length="0.006" radius="0.170"/>
         </geometry>
      </collision>
      <inertial>
         <mass value="0.520"/>
         <origin xyz="0 0 0"/>
         <inertia ixx="0.003328" ixy="0.0" ixz="0.0" iyy="0.003328" iyz="0.0" izz="0.006656"/>
      </inertial>
</link>

<joint name="plate_middle_joint" type="fixed">
      <origin rpy="0 0 0" xyz="-0.01364 0.0 0.1874"/>
      <parent link="base_link"/>
      <child link="plate_middle_link"/>
</joint>


<!--ENCIMA DE LA SEGUNDA PLATAFORMA  -->
<link name="pole_top_0_link">
      <visual>
         <origin rpy="0 0 0" xyz=" 0 0 0"/>
         <geometry>
            <!--
            <mesh filename="package://turtlebot_description/meshes/stacks/hexagons/pole_top.dae" />
            -->
            <mesh filename="package://my_mira_description/meshes/kobuki_meshes/stacks/hexagons/pole_top.dae"/>
         </geometry>
      </visual>
      <collision>
         <origin rpy="0 0 0" xyz="0 0 0"/>
         <geometry>
            <cylinder length="0.2032" radius="0.006"/>
         </geometry>
      </collision>
      <inertial>
         <mass value="0.060"/>
         <origin xyz="0 0 0"/>
         <inertia ixx="0.000206991" ixy="0.0" ixz="0.0" iyy="0.000206991" iyz="0.0" izz="0.000001080"/>
      </inertial>
</link>

<joint name="pole_top_0_joint" type="fixed">
      <origin rpy="0 0 0" xyz="0.0381 0.1505 0.292"/>
      <parent link="base_link"/>
      <child link="pole_top_0_link"/>
</joint>


<link name="pole_top_1_link">
      <visual>
         <origin rpy="0 0 0" xyz=" 0 0 0"/>
         <geometry>
            <!--
            <mesh filename="package://turtlebot_description/meshes/stacks/hexagons/pole_top.dae" />
            -->
            <mesh filename="package://my_mira_description/meshes/kobuki_meshes/stacks/hexagons/pole_top.dae"/>
         </geometry>
      </visual>
      <collision>
         <origin rpy="0 0 0" xyz="0 0 0"/>
         <geometry>
            <cylinder length="0.2032" radius="0.006"/>
         </geometry>
      </collision>
      <inertial>
         <mass value="0.060"/>
         <origin xyz="0 0 0"/>
         <inertia ixx="0.000206991" ixy="0.0" ixz="0.0" iyy="0.000206991" iyz="0.0" izz="0.000001080"/>
      </inertial>
</link>

<joint name="pole_top_1_joint" type="fixed">
      <origin rpy="0 0 0" xyz="0.0381 -0.1505 0.292"/>
      <parent link="base_link"/>
      <child link="pole_top_1_link"/>
</joint>

<link name="pole_top_2_link">
      <visual>
         <origin rpy="0 0 0" xyz=" 0 0 0"/>
         <geometry>
            <!--
            <mesh filename="package://turtlebot_description/meshes/stacks/hexagons/pole_top.dae" />
            -->
            <mesh filename="package://my_mira_description/meshes/kobuki_meshes/stacks/hexagons/pole_top.dae"/>
         </geometry>
      </visual>
      <collision>
         <origin rpy="0 0 0" xyz="0 0 0"/>
         <geometry>
            <cylinder length="0.2032" radius="0.006"/>
         </geometry>
      </collision>
      <inertial>
         <mass value="0.060"/>
         <origin xyz="0 0 0"/>
         <inertia ixx="0.000206991" ixy="0.0" ixz="0.0" iyy="0.000206991" iyz="0.0" izz="0.000001080"/>
      </inertial>
</link>

<joint name="pole_top_2_joint" type="fixed">
      <origin rpy="0 0 0" xyz="-0.0381 0.1505 0.292"/>
      <parent link="base_link"/>
      <child link="pole_top_2_link"/>
</joint>


<joint name="pole_top_3_joint" type="fixed">
      <origin rpy="0 0 0" xyz="-0.0381 -0.1505 0.292"/>
      <parent link="base_link"/>
      <child link="pole_top_3_link"/>
</joint>
 <link name="pole_top_3_link">
      <visual>
         <origin rpy="0 0 0" xyz=" 0 0 0"/>
         <geometry>
            <!--
            <mesh filename="package://turtlebot_description/meshes/stacks/hexagons/pole_top.dae" />
            -->
            <mesh filename="package://my_mira_description/meshes/kobuki_meshes/stacks/hexagons/pole_top.dae"/>
         </geometry>
      </visual>
    <collision>
         <origin rpy="0 0 0" xyz="0 0 0"/>
         <geometry>
            <cylinder length="0.2032" radius="0.006"/>
         </geometry>
      </collision>
      <inertial>
         <mass value="0.060"/>
         <origin xyz="0 0 0"/>
         <inertia ixx="0.000206991" ixy="0.0" ixz="0.0" iyy="0.000206991" iyz="0.0" izz="0.000001080"/>
      </inertial>
</link>

<link name="plate_top_link">
      <visual>
         <origin rpy="0 0 0" xyz="0 0 0"/>
         <geometry>
            <mesh filename="package://my_mira_description/meshes/kobuki_meshes/stacks/hexagons/plate_top.dae"/>
         </geometry>
      </visual>
       <collision>
         <origin rpy="0 0 0" xyz="0.01364 0 0"/>
         <geometry>
            <cylinder length="0.006" radius="0.170"/>
         </geometry>
      </collision>
      <inertial>
         <mass value="0.520"/>
         <origin xyz="0 0 0"/>
         <inertia ixx="0.003328" ixy="0.0" ixz="0.0" iyy="0.003328" iyz="0.0" izz="0.006656"/>
      </inertial>
</link>

 <joint name="plate_top_joint" type="fixed">
      <origin rpy="0 0 0" xyz="-0.01364 0.0  0.3966"/>
      <parent link="base_link"/>
      <child link="plate_top_link"/>
</joint>

<!--PALOS PARA LA KINNECT  -->

<link name="pole_kinect_0_link">
      <visual>
         <origin rpy="0 0 0" xyz="0 0 -0.01"/>
         <geometry>
            <!-- <cylinder radius="0.005" length="0.05" /> -->
            <cylinder length="0.0936" radius="0.006"/>
            <!-- <mesh filename="package://my_mira_description/meshes/kobuki_meshes/sensors/sensor_pole.dae" /> -->
         </geometry>
      </visual>
       <collision>
         <origin rpy="0 0 0" xyz="0 0 0"/>
         <geometry>
            <cylinder length="0.0936" radius="0.006"/>
         </geometry>
      </collision>
      <inertial>
         <mass value="0.020"/>
         <origin xyz="0 0 0"/>
         <inertia ixx="0.000014782" ixy="0.0" ixz="0.0" iyy="0.000014782" iyz="0.0" izz="0.000000360"/>
      </inertial>
</link>

<joint name="pole_kinect_0_joint" type="fixed">
      <origin rpy="0 0 0" xyz="-0.1024 0.098 0.2372"/>
      <parent link="base_link"/>
      <child link="pole_kinect_0_link"/>
</joint>


<joint name="pole_kinect_1_joint" type="fixed">
      <origin rpy="0 0 0" xyz="-0.1024 -0.098 0.2372"/>
      <parent link="base_link"/>
      <child link="pole_kinect_1_link"/>
</joint>

<link name="pole_kinect_1_link">
      <visual>
         <origin rpy="0 0 0" xyz="0 0 -0.01"/>
         <geometry>
            <!-- <mesh filename="package://my_mira_description/meshes/sensors/sensor_pole.dae" /> -->
            <cylinder length="0.0936" radius="0.006"/>
         </geometry>
      </visual>
      <collision>
         <origin rpy="0 0 0" xyz="0 0 0"/>
         <geometry>
            <cylinder length="0.0936" radius="0.006"/>
         </geometry>
      </collision>
      <inertial>
         <mass value="0.020"/>
         <origin xyz="0 0 0"/>
         <inertia ixx="0.000014782" ixy="0.0" ixz="0.0" iyy="0.000014782" iyz="0.0" izz="0.000000360"/>
      </inertial>
</link>


<joint name="mount_asus_xtion_pro_joint" type="fixed">
      <origin rpy="0 0 0" xyz="-0.1024    0.0 0.272"/>
      <parent link="base_link"/>
      <child link="mount_asus_xtion_pro_link"/>
</joint>

<link name="mount_asus_xtion_pro_link">
      <visual>
         <!-- <origin rpy="-1.57079632679 0 0" xyz="0 0 0" /> -->
         <origin rpy="0 0 0" xyz="0.0 0.0 0.0"/>
         <geometry>
            <!--<mesh filename="package://my_mira_description/meshes/xtion_pro_stack.dae" /> -->
            <!-- <box size="0.0330 0.2760 0.0120" /> -->
             <box size="0.0330 0.2760 0.0120"/>
         </geometry>
      </visual>
       <collision>
         <origin rpy="0 0 0" xyz="0.0 0.0 0.0"/>
         <geometry>
            <box size="0.0330 0.2760 0.0120"/>
         </geometry>
      </collision>
      <inertial>
         <mass value="0.170"/>
         <origin xyz="0 0 0"/>
         <inertia ixx="0.001152600" ixy="0.0" ixz="0.0" iyy="0.000148934" iyz="0.0" izz="0.001154654"/>
      </inertial>
      
</link>



<!-- CAMARA RGBD -->

<joint name="camera_rgb_joint" type="fixed">
      <origin rpy="0 0 0" xyz="-0.087 0.0205 0.287"/>
      <parent link="base_link"/>
      <child link="camera_rgb_frame"/>
</joint>
<link name="camera_rgb_frame"/>

<joint name="camera_rgb_optical_joint" type="fixed">
      <origin rpy="-1.57079632679 0 -1.57079632679" xyz="0 0    0"/>
      <parent link="camera_rgb_frame"/>
      <child link="camera_rgb_optical_frame"/>
   </joint>
<link name="camera_rgb_optical_frame"/>


 <joint name="camera_joint" type="fixed">
      <origin rpy="0 0 0" xyz="0 -0.022 0"/>
      <parent link="camera_rgb_frame"/>
      <child link="camera_link"/>
   </joint>

<link name="camera_link">
      <visual>
         <!-- <origin rpy="0 0 0" xyz="-0.015 0.0035 0.004" /> -->
        <!-- <origin rpy="0 0 1.57079632679" xyz="-0.015 0.0035 0.004" /> -->
        <origin rpy="0 0 1.57079632679" xyz="-0.015 0.0035 0.0272"/>
         <geometry>
            <mesh filename="package://my_mira_description/meshes/kinect.dae"/> 
            <!--<box size="0.0730 0.2760 0.0720" /> -->
         </geometry>
      </visual>
      <collision>
         <origin rpy="0 0 0" xyz="0.0 0.0 0.0"/>
         <geometry>
            <box size="0.0730 0.2760 0.0720"/>
         </geometry>
      </collision>
      <inertial>
         <mass value="0.170"/>
         <origin xyz="0 0 0"/>
         <inertia ixx="0.001152600" ixy="0.0" ixz="0.0" iyy="0.000148934" iyz="0.0" izz="0.001154654"/>
      </inertial>
</link>

   
<!-- SCANNER LASER -->


<link name="laser_sensor_link">
      <visual>
         <origin rpy="0 0 0" xyz="0 0 0"/>
         <geometry>
            <mesh filename="package://my_mira_description/meshes/kobuki_meshes/sensors/hokuyo.dae"/>
         </geometry>
      </visual>
</link>


<joint name="laser_sensor_joint" type="fixed">
      <origin rpy="0 0 0" xyz="0.0 0.0 0.435"/>
      <parent link="base_link"/>
      <child link="laser_sensor_link"/>
</joint>


<!-- anadimos los plugins... -->
<!-- plugin de la base para el control diferencial... -->

<gazebo>
      <plugin filename="libgazebo_ros_diff_drive.so" name="differential_drive_controller">
         <alwaysOn>true</alwaysOn>
         <updateRate>20</updateRate>
         <publishTf> true </publishTf>
         <leftJoint>wheel_right_joint</leftJoint>
         <rightJoint>wheel_left_joint</rightJoint>
         <wheelSeparation>.230</wheelSeparation>
         <wheelDiameter>0.070</wheelDiameter>
         <torque>5.0</torque>
         <commandTopic>/cmd_vel</commandTopic>
         <odometrySource>world</odometrySource> <!-- 'encoder' instead of 'world' is also possible -->
         <odometryTopic>/odom</odometryTopic> <!-- relative/name ,  /global/name  -->
         <odometryFrame>/odom</odometryFrame>
         <robotBaseFrame>/base_footprint</robotBaseFrame>
         <publishOdomTF> true </publishOdomTF>
         <publishWheelJointState>true</publishWheelJointState>
        <!-- Set to true to publish transforms for the wheel links, defaults to false -->
         <publishWheelTF>true</publishWheelTF>
         <wheelAcceleration> 0 </wheelAcceleration>
         <wheelTorque> 5.0 </wheelTorque>
         <legacyMode>true</legacyMode>
         <rosDebugLevel> na </rosDebugLevel> <!-- <rosDebugLevel>Debug</rosDebugLevel> -->
      </plugin>
   </gazebo>

<!-- plugin del laser... -->

<gazebo reference="laser_sensor_link">
      <sensor name="laser_sensor" type="gpu_ray">
         <pose>0 0 0 0 0 0</pose>
         <visualize>false</visualize>
         <update_rate>40</update_rate>
         <ray>
            <scan>
               <horizontal>
                  <samples>720</samples>
                  <resolution>1</resolution>
                  <min_angle>-1.570796</min_angle>
                  <max_angle>1.570796</max_angle>
                  <!--
                  <min_angle>-2.26889</min_angle>
                  <max_angle>2.268899</max_angle>
                  -->
               </horizontal>
            </scan>
            <range>
               <min>0.10</min>
               <max>30.0</max>
               <resolution>0.01</resolution>
            </range>
            <noise>
               <type>gaussian</type>
               <mean>0.0</mean>
               <stddev>0.01</stddev>
            </noise>
         </ray>
         <plugin filename="libgazebo_ros_gpu_laser.so" name="gazebo_ros_head_hokuyo_controller">
            <topicName>/kobuki/laser/scan</topicName>
            <frameName>laser_sensor_link</frameName>
         </plugin>
      </sensor>
</gazebo>



</robot>